[2024-01-19 14:51:57,439] 96 werkzeug - INFO - [31m[1mWARNING: This is a development server. Do not use it in a production deployment. Use a production WSGI server instead.[0m
 * Running on all addresses (0.0.0.0)
 * Running on http://127.0.0.1:8000
 * Running on http://192.168.0.222:8000
[2024-01-19 14:51:57,439] 96 werkzeug - INFO - [33mPress CTRL+C to quit[0m
[2024-01-19 14:52:17,900] 96 werkzeug - INFO - 127.0.0.1 - - [19/Jan/2024 14:52:17] "GET / HTTP/1.1" 200 -
[2024-01-19 14:52:18,048] 96 werkzeug - INFO - 127.0.0.1 - - [19/Jan/2024 14:52:18] "[33mGET /favicon.ico HTTP/1.1[0m" 404 -
[2024-01-19 14:52:25,481] 96 werkzeug - INFO - 127.0.0.1 - - [19/Jan/2024 14:52:25] "GET /predict HTTP/1.1" 200 -
[2024-01-19 14:53:32,650] 68 root - INFO - Dataframe Gathered
[2024-01-19 14:53:32,651] 53 root - INFO - Exception Occured in load_object function utils
[2024-01-19 14:53:32,651] 1414 app - ERROR - Exception on /predict [POST]
Traceback (most recent call last):
  File "/home/ml/MLOPS/src/utils/utils.py", line 50, in load_object
    with open(file_path,'rb') as file_obj:
FileNotFoundError: [Errno 2] No such file or directory: 'artifacts/preprocessor.pkl'

During handling of the above exception, another exception occurred:

Traceback (most recent call last):
  File "/home/ml/MLOPS/src/pipeline/prediction_pipeline.py", line 20, in predict
    preprocessor=load_object(preprocessor_path)
  File "/home/ml/MLOPS/src/utils/utils.py", line 54, in load_object
    raise customexception(e,sys)
src.exception.exception.customexception: Error occured in python script name [/home/ml/MLOPS/src/utils/utils.py] line number [50] error message [[Errno 2] No such file or directory: 'artifacts/preprocessor.pkl']

During handling of the above exception, another exception occurred:

Traceback (most recent call last):
  File "/home/ml/mlops_env/mlops_env/lib/python3.10/site-packages/flask/app.py", line 2190, in wsgi_app
    response = self.full_dispatch_request()
  File "/home/ml/mlops_env/mlops_env/lib/python3.10/site-packages/flask/app.py", line 1486, in full_dispatch_request
    rv = self.handle_user_exception(e)
  File "/home/ml/mlops_env/mlops_env/lib/python3.10/site-packages/flask/app.py", line 1484, in full_dispatch_request
    rv = self.dispatch_request()
  File "/home/ml/mlops_env/mlops_env/lib/python3.10/site-packages/flask/app.py", line 1469, in dispatch_request
    return self.ensure_sync(self.view_functions[rule.endpoint])(**view_args)
  File "/home/ml/MLOPS/app.py", line 32, in predict_datapoint
    pred=predict_pipeline.predict(final_data)
  File "/home/ml/MLOPS/src/pipeline/prediction_pipeline.py", line 29, in predict
    raise customexception(e,sys)
src.exception.exception.customexception: Error occured in python script name [/home/ml/MLOPS/src/pipeline/prediction_pipeline.py] line number [20] error message [Error occured in python script name [/home/ml/MLOPS/src/utils/utils.py] line number [50] error message [[Errno 2] No such file or directory: 'artifacts/preprocessor.pkl']]
[2024-01-19 14:53:32,655] 96 werkzeug - INFO - 127.0.0.1 - - [19/Jan/2024 14:53:32] "[35m[1mPOST /predict HTTP/1.1[0m" 500 -
